Workbook

Sheet BUI
A1: =IFERROR(__xludf.DUMMYFUNCTION("IMPORTDATA(""https://rest.fnar.net/csv/buildingcosts"")"),"Key") -> Key | B1: =IFERROR(__xludf.DUMMYFUNCTION("""COMPUTED_VALUE"""),"Building") -> Building | C1: =IFERROR(__xludf.DUMMYFUNCTION("""COMPUTED_VALUE"""),"Material") -> Material | D1: =IFERROR(__xludf.DUMMYFUNCTION("""COMPUTED_VALUE"""),"Amount") -> Amount | G1: =IFERROR(__xludf.DUMMYFUNCTION("IMPORTDATA(""https://rest.fnar.net/csv/buildings"")"),"Ticker") -> Ticker | H1: =IFERROR(__xludf.DUMMYFUNCTION("""COMPUTED_VALUE"""),"Name") -> Name | I1: =IFERROR(__xludf.DUMMYFUNCTION("""COMPUTED_VALUE"""),"Area") -> Area | J1: =IFERROR(__xludf.DUMMYFUNCTION("""COMPUTED_VALUE"""),"Expertise") -> Expertise
A2: =IFERROR(__xludf.DUMMYFUNCTION("""COMPUTED_VALUE"""),"4DA-ADS") -> 4DA-ADS | B2: =IFERROR(__xludf.DUMMYFUNCTION("""COMPUTED_VALUE"""),"4DA") -> 4DA | C2: =IFERROR(__xludf.DUMMYFUNCTION("""COMPUTED_VALUE"""),"ADS") -> ADS | D2: =IFERROR(__xludf.DUMMYFUNCTION("""COMPUTED_VALUE"""),1.0) -> 1 | G2: =IFERROR(__xludf.DUMMYFUNCTION("""COMPUTED_VALUE"""),"4DA") -> 4DA | H2: =IFERROR(__xludf.DUMMYFUNCTION("""COMPUTED_VALUE"""),"planetaryProjectComfortBig") -> planetaryProjectComfortBig | I2: =IFERROR(__xludf.DUMMYFUNCTION("""COMPUTED_VALUE"""),1000.0) -> 1000
A3: =IFERROR(__xludf.DUMMYFUNCTION("""COMPUTED_VALUE"""),"4DA-BMF") -> 4DA-BMF | B3: =IFERROR(__xludf.DUMMYFUNCTION("""COMPUTED_VALUE"""),"4DA") -> 4DA | C3: =IFERROR(__xludf.DUMMYFUNCTION("""COMPUTED_VALUE"""),"BMF") -> BMF | D3: =IFERROR(__xludf.DUMMYFUNCTION("""COMPUTED_VALUE"""),2.0) -> 2 | G3: =IFERROR(__xludf.DUMMYFUNCTION("""COMPUTED_VALUE"""),"AAF") -> AAF | H3: =IFERROR(__xludf.DUMMYFUNCTION("""COMPUTED_VALUE"""),"advancedAppliancesFactory") -> advancedAppliancesFactory | I3: =IFERROR(__xludf.DUMMYFUNCTION("""COMPUTED_VALUE"""),50.0) -> 50 | J3: =IFERROR(__xludf.DUMMYFUNCTION("""COMPUTED_VALUE"""),"MANUFACTURING") -> MANUFACTURING
A4: =IFERROR(__xludf.DUMMYFUNCTION("""COMPUTED_VALUE"""),"4DA-FUN") -> 4DA-FUN | B4: =IFERROR(__xludf.DUMMYFUNCTION("""COMPUTED_VALUE"""),"4DA") -> 4DA | C4: =IFERROR(__xludf.DUMMYFUNCTION("""COMPUTED_VALUE"""),"FUN") -> FUN | D4: =IFERROR(__xludf.DUMMYFUNCTION("""COMPUTED_VALUE"""),10.0) -> 10 | G4: =IFERROR(__xludf.DUMMYFUNCTION("""COMPUTED_VALUE"""),"ACA") -> ACA | H4: =IFERROR(__xludf.DUMMYFUNCTION("""COMPUTED_VALUE"""),"planetaryProjectComfortCulture") -> planetaryProjectComfortCulture | I4: =IFERROR(__xludf.DUMMYFUNCTION("""COMPUTED_VALUE"""),1000.0) -> 1000
A5: =IFERROR(__xludf.DUMMYFUNCTION("""COMPUTED_VALUE"""),"4DA-LBH") -> 4DA-LBH | B5: =IFERROR(__xludf.DUMMYFUNCTION("""COMPUTED_VALUE"""),"4DA") -> 4DA | C5: =IFERROR(__xludf.DUMMYFUNCTION("""COMPUTED_VALUE"""),"LBH") -> LBH | D5: =IFERROR(__xludf.DUMMYFUNCTION("""COMPUTED_VALUE"""),42.0) -> 42 | G5: =IFERROR(__xludf.DUMMYFUNCTION("""COMPUTED_VALUE"""),"ADM") -> ADM | H5: =IFERROR(__xludf.DUMMYFUNCTION("""COMPUTED_VALUE"""),"planetaryProjectAdminCenter") -> planetaryProjectAdminCenter | I5: =IFERROR(__xludf.DUMMYFUNCTION("""COMPUTED_VALUE"""),400.0) -> 400
A6: =IFERROR(__xludf.DUMMYFUNCTION("""COMPUTED_VALUE"""),"4DA-LDE") -> 4DA-LDE | B6: =IFERROR(__xludf.DUMMYFUNCTION("""COMPUTED_VALUE"""),"4DA") -> 4DA | C6: =IFERROR(__xludf.DUMMYFUNCTION("""COMPUTED_VALUE"""),"LDE") -> LDE | D6: =IFERROR(__xludf.DUMMYFUNCTION("""COMPUTED_VALUE"""),42.0) -> 42 | G6: =IFERROR(__xludf.DUMMYFUNCTION("""COMPUTED_VALUE"""),"AML") -> AML | H6: =IFERROR(__xludf.DUMMYFUNCTION("""COMPUTED_VALUE"""),"advancedMaterialLab") -> advancedMaterialLab | I6: =IFERROR(__xludf.DUMMYFUNCTION("""COMPUTED_VALUE"""),45.0) -> 45 | J6: =IFERROR(__xludf.DUMMYFUNCTION("""COMPUTED_VALUE"""),"CHEMISTRY") -> CHEMISTRY
A7: =IFERROR(__xludf.DUMMYFUNCTION("""COMPUTED_VALUE"""),"4DA-LIT") -> 4DA-LIT | B7: =IFERROR(__xludf.DUMMYFUNCTION("""COMPUTED_VALUE"""),"4DA") -> 4DA | C7: =IFERROR(__xludf.DUMMYFUNCTION("""COMPUTED_VALUE"""),"LIT") -> LIT | D7: =IFERROR(__xludf.DUMMYFUNCTION("""COMPUTED_VALUE"""),2.0) -> 2 | G7: =IFERROR(__xludf.DUMMYFUNCTION("""COMPUTED_VALUE"""),"APF") -> APF | H7: =IFERROR(__xludf.DUMMYFUNCTION("""COMPUTED_VALUE"""),"appliancesFactory") -> appliancesFactory | I7: =IFERROR(__xludf.DUMMYFUNCTION("""COMPUTED_VALUE"""),40.0) -> 40 | J7: =IFERROR(__xludf.DUMMYFUNCTION("""COMPUTED_VALUE"""),"MANUFACTURING") -> MANUFACTURING
A8: =IFERROR(__xludf.DUMMYFUNCTION("""COMPUTED_VALUE"""),"4DA-LSE") -> 4DA-LSE | B8: =IFERROR(__xludf.DUMMYFUNCTION("""COMPUTED_VALUE"""),"4DA") -> 4DA | C8: =IFERROR(__xludf.DUMMYFUNCTION("""COMPUTED_VALUE"""),"LSE") -> LSE | D8: =IFERROR(__xludf.DUMMYFUNCTION("""COMPUTED_VALUE"""),42.0) -> 42 | G8: =IFERROR(__xludf.DUMMYFUNCTION("""COMPUTED_VALUE"""),"ART") -> ART | H8: =IFERROR(__xludf.DUMMYFUNCTION("""COMPUTED_VALUE"""),"planetaryProjectCultureSmall") -> planetaryProjectCultureSmall | I8: =IFERROR(__xludf.DUMMYFUNCTION("""COMPUTED_VALUE"""),500.0) -> 500
A9: =IFERROR(__xludf.DUMMYFUNCTION("""COMPUTED_VALUE"""),"4DA-LTA") -> 4DA-LTA | B9: =IFERROR(__xludf.DUMMYFUNCTION("""COMPUTED_VALUE"""),"4DA") -> 4DA | C9: =IFERROR(__xludf.DUMMYFUNCTION("""COMPUTED_VALUE"""),"LTA") -> LTA | D9: =IFERROR(__xludf.DUMMYFUNCTION("""COMPUTED_VALUE"""),24.0) -> 24 | G9: =IFERROR(__xludf.DUMMYFUNCTION("""COMPUTED_VALUE"""),"ASM") -> ASM | H9: =IFERROR(__xludf.DUMMYFUNCTION("""COMPUTED_VALUE"""),"advancedSmelter") -> advancedSmelter | I9: =IFERROR(__xludf.DUMMYFUNCTION("""COMPUTED_VALUE"""),34.0) -> 34 | J9: =IFERROR(__xludf.DUMMYFUNCTION("""COMPUTED_VALUE"""),"METALLURGY") -> METALLURGY
A10: =IFERROR(__xludf.DUMMYFUNCTION("""COMPUTED_VALUE"""),"4DA-MCG") -> 4DA-MCG | B10: =IFERROR(__xludf.DUMMYFUNCTION("""COMPUTED_VALUE"""),"4DA") -> 4DA | C10: =IFERROR(__xludf.DUMMYFUNCTION("""COMPUTED_VALUE"""),"MCG") -> MCG | D10: =IFERROR(__xludf.DUMMYFUNCTION("""COMPUTED_VALUE"""),600.0) -> 600 | G10: =IFERROR(__xludf.DUMMYFUNCTION("""COMPUTED_VALUE"""),"BMP") -> BMP | H10: =IFERROR(__xludf.DUMMYFUNCTION("""COMPUTED_VALUE"""),"basicMaterialsPlant") -> basicMaterialsPlant | I10: =IFERROR(__xludf.DUMMYFUNCTION("""COMPUTED_VALUE"""),12.0) -> 12 | J10: =IFERROR(__xludf.DUMMYFUNCTION("""COMPUTED_VALUE"""),"MANUFACTURING") -> MANUFACTURING
A11: =IFERROR(__xludf.DUMMYFUNCTION("""COMPUTED_VALUE"""),"4DA-TRU") -> 4DA-TRU | B11: =IFERROR(__xludf.DUMMYFUNCTION("""COMPUTED_VALUE"""),"4DA") -> 4DA | C11: =IFERROR(__xludf.DUMMYFUNCTION("""COMPUTED_VALUE"""),"TRU") -> TRU | D11: =IFERROR(__xludf.DUMMYFUNCTION("""COMPUTED_VALUE"""),40.0) -> 40 | G11: =IFERROR(__xludf.DUMMYFUNCTION("""COMPUTED_VALUE"""),"CFL") -> CFL | H11: =IFERROR(__xludf.DUMMYFUNCTION("""COMPUTED_VALUE"""),"corporationProjectFTLLaboratory") -> corporationProjectFTLLaboratory | I11: =IFERROR(__xludf.DUMMYFUNCTION("""COMPUTED_VALUE"""),100.0) -> 100
A12: =IFERROR(__xludf.DUMMYFUNCTION("""COMPUTED_VALUE"""),"AAF-ABH") -> AAF-ABH | B12: =IFERROR(__xludf.DUMMYFUNCTION("""COMPUTED_VALUE"""),"AAF") -> AAF | C12: =IFERROR(__xludf.DUMMYFUNCTION("""COMPUTED_VALUE"""),"ABH") -> ABH | D12: =IFERROR(__xludf.DUMMYFUNCTION("""COMPUTED_VALUE"""),6.0) -> 6 | G12: =IFERROR(__xludf.DUMMYFUNCTION("""COMPUTED_VALUE"""),"CHP") -> CHP | H12: =IFERROR(__xludf.DUMMYFUNCTION("""COMPUTED_VALUE"""),"chemPlant") -> chemPlant | I12: =IFERROR(__xludf.DUMMYFUNCTION("""COMPUTED_VALUE"""),18.0) -> 18 | J12: =IFERROR(__xludf.DUMMYFUNCTION("""COMPUTED_VALUE"""),"CHEMISTRY") -> CHEMISTRY
A13: =IFERROR(__xludf.DUMMYFUNCTION("""COMPUTED_VALUE"""),"AAF-ADE") -> AAF-ADE | B13: =IFERROR(__xludf.DUMMYFUNCTION("""COMPUTED_VALUE"""),"AAF") -> AAF | C13: =IFERROR(__xludf.DUMMYFUNCTION("""COMPUTED_VALUE"""),"ADE") -> ADE | D13: =IFERROR(__xludf.DUMMYFUNCTION("""COMPUTED_VALUE"""),8.0) -> 8 | G13: =IFERROR(__xludf.DUMMYFUNCTION("""COMPUTED_VALUE"""),"CIM") -> CIM | H13: =IFERROR(__xludf.DUMMYFUNCTION("""COMPUTED_VALUE"""),"corporationProjectImmortality") -> corporationProjectImmortality | I13: =IFERROR(__xludf.DUMMYFUNCTION("""COMPUTED_VALUE"""),100.0) -> 100
A14: =IFERROR(__xludf.DUMMYFUNCTION("""COMPUTED_VALUE"""),"AAF-ASE") -> AAF-ASE | B14: =IFERROR(__xludf.DUMMYFUNCTION("""COMPUTED_VALUE"""),"AAF") -> AAF | C14: =IFERROR(__xludf.DUMMYFUNCTION("""COMPUTED_VALUE"""),"ASE") -> ASE | D14: =IFERROR(__xludf.DUMMYFUNCTION("""COMPUTED_VALUE"""),8.0) -> 8 | G14: =IFERROR(__xludf.DUMMYFUNCTION("""COMPUTED_VALUE"""),"CLF") -> CLF | H14: =IFERROR(__xludf.DUMMYFUNCTION("""COMPUTED_VALUE"""),"clothingFactory") -> clothingFactory | I14: =IFERROR(__xludf.DUMMYFUNCTION("""COMPUTED_VALUE"""),37.0) -> 37 | J14: =IFERROR(__xludf.DUMMYFUNCTION("""COMPUTED_VALUE"""),"MANUFACTURING") -> MANUFACTURING
A15: =IFERROR(__xludf.DUMMYFUNCTION("""COMPUTED_VALUE"""),"AAF-ATA") -> AAF-ATA | B15: =IFERROR(__xludf.DUMMYFUNCTION("""COMPUTED_VALUE"""),"AAF") -> AAF | C15: =IFERROR(__xludf.DUMMYFUNCTION("""COMPUTED_VALUE"""),"ATA") -> ATA | D15: =IFERROR(__xludf.DUMMYFUNCTION("""COMPUTED_VALUE"""),1.0) -> 1 | G15: =IFERROR(__xludf.DUMMYFUNCTION("""COMPUTED_VALUE"""),"CLR") -> CLR | H15: =IFERROR(__xludf.DUMMYFUNCTION("""COMPUTED_VALUE"""),"cleanRoom") -> cleanRoom | I15: =IFERROR(__xludf.DUMMYFUNCTION("""COMPUTED_VALUE"""),27.0) -> 27 | J15: =IFERROR(__xludf.DUMMYFUNCTION("""COMPUTED_VALUE"""),"ELECTRONICS") -> ELECTRONICS
A16: =IFERROR(__xludf.DUMMYFUNCTION("""COMPUTED_VALUE"""),"AAF-TRU") -> AAF-TRU | B16: =IFERROR(__xludf.DUMMYFUNCTION("""COMPUTED_VALUE"""),"AAF") -> AAF | C16: =IFERROR(__xludf.DUMMYFUNCTION("""COMPUTED_VALUE"""),"TRU") -> TRU | D16: =IFERROR(__xludf.DUMMYFUNCTION("""COMPUTED_VALUE"""),8.0) -> 8 | G16: =IFERROR(__xludf.DUMMYFUNCTION("""COMPUTED_VALUE"""),"CM") -> CM | H16: =IFERROR(__xludf.DUMMYFUNCTION("""COMPUTED_VALUE"""),"coreModule") -> coreModule | I16: =IFERROR(__xludf.DUMMYFUNCTION("""COMPUTED_VALUE"""),25.0) -> 25
A17: =IFERROR(__xludf.DUMMYFUNCTION("""COMPUTED_VALUE"""),"ACA-DEC") -> ACA-DEC | B17: =IFERROR(__xludf.DUMMYFUNCTION("""COMPUTED_VALUE"""),"ACA") -> ACA | C17: =IFERROR(__xludf.DUMMYFUNCTION("""COMPUTED_VALUE"""),"DEC") -> DEC | D17: =IFERROR(__xludf.DUMMYFUNCTION("""COMPUTED_VALUE"""),32.0) -> 32 | G17: =IFERROR(__xludf.DUMMYFUNCTION("""COMPUTED_VALUE"""),"COG") -> COG | H17: =IFERROR(__xludf.DUMMYFUNCTION("""COMPUTED_VALUE"""),"planetaryProjectCogc") -> planetaryProjectCogc | I17: =IFERROR(__xludf.DUMMYFUNCTION("""COMPUTED_VALUE"""),1000.0) -> 1000
A18: =IFERROR(__xludf.DUMMYFUNCTION("""COMPUTED_VALUE"""),"ACA-MCG") -> ACA-MCG | B18: =IFERROR(__xludf.DUMMYFUNCTION("""COMPUTED_VALUE"""),"ACA") -> ACA | C18: =IFERROR(__xludf.DUMMYFUNCTION("""COMPUTED_VALUE"""),"MCG") -> MCG | D18: =IFERROR(__xludf.DUMMYFUNCTION("""COMPUTED_VALUE"""),300.0) -> 300 | G18: =IFERROR(__xludf.DUMMYFUNCTION("""COMPUTED_VALUE"""),"COL") -> COL | H18: =IFERROR(__xludf.DUMMYFUNCTION("""COMPUTED_VALUE"""),"collector") -> collector | I18: =IFERROR(__xludf.DUMMYFUNCTION("""COMPUTED_VALUE"""),15.0) -> 15 | J18: =IFERROR(__xludf.DUMMYFUNCTION("""COMPUTED_VALUE"""),"RESOURCE_EXTRACTION") -> RESOURCE_EXTRACTION
A19: =IFERROR(__xludf.DUMMYFUNCTION("""COMPUTED_VALUE"""),"ACA-RBH") -> ACA-RBH | B19: =IFERROR(__xludf.DUMMYFUNCTION("""COMPUTED_VALUE"""),"ACA") -> ACA | C19: =IFERROR(__xludf.DUMMYFUNCTION("""COMPUTED_VALUE"""),"RBH") -> RBH | D19: =IFERROR(__xludf.DUMMYFUNCTION("""COMPUTED_VALUE"""),16.0) -> 16 | G19: =IFERROR(__xludf.DUMMYFUNCTION("""COMPUTED_VALUE"""),"COR") -> COR | H19: =IFERROR(__xludf.DUMMYFUNCTION("""COMPUTED_VALUE"""),"corporationProjectHeadquarters") -> corporationProjectHeadquarters | I19: =IFERROR(__xludf.DUMMYFUNCTION("""COMPUTED_VALUE"""),100.0) -> 100
A20: =IFERROR(__xludf.DUMMYFUNCTION("""COMPUTED_VALUE"""),"ACA-RDE") -> ACA-RDE | B20: =IFERROR(__xludf.DUMMYFUNCTION("""COMPUTED_VALUE"""),"ACA") -> ACA | C20: =IFERROR(__xludf.DUMMYFUNCTION("""COMPUTED_VALUE"""),"RDE") -> RDE | D20: =IFERROR(__xludf.DUMMYFUNCTION("""COMPUTED_VALUE"""),24.0) -> 24 | G20: =IFERROR(__xludf.DUMMYFUNCTION("""COMPUTED_VALUE"""),"CRC") -> CRC | H20: =IFERROR(__xludf.DUMMYFUNCTION("""COMPUTED_VALUE"""),"corporationProjectRepresentationCenter") -> corporationProjectRepresentationCenter | I20: =IFERROR(__xludf.DUMMYFUNCTION("""COMPUTED_VALUE"""),100.0) -> 100
A21: =IFERROR(__xludf.DUMMYFUNCTION("""COMPUTED_VALUE"""),"ACA-RSE") -> ACA-RSE | B21: =IFERROR(__xludf.DUMMYFUNCTION("""COMPUTED_VALUE"""),"ACA") -> ACA | C21: =IFERROR(__xludf.DUMMYFUNCTION("""COMPUTED_VALUE"""),"RSE") -> RSE | D21: =IFERROR(__xludf.DUMMYFUNCTION("""COMPUTED_VALUE"""),24.0) -> 24 | G21: =IFERROR(__xludf.DUMMYFUNCTION("""COMPUTED_VALUE"""),"CTE") -> CTE | H21: =IFERROR(__xludf.DUMMYFUNCTION("""COMPUTED_VALUE"""),"corporationProjectTerraforming") -> corporationProjectTerraforming | I21: =IFERROR(__xludf.DUMMYFUNCTION("""COMPUTED_VALUE"""),100.0) -> 100
A22: =IFERROR(__xludf.DUMMYFUNCTION("""COMPUTED_VALUE"""),"ACA-RTA") -> ACA-RTA | B22: =IFERROR(__xludf.DUMMYFUNCTION("""COMPUTED_VALUE"""),"ACA") -> ACA | C22: =IFERROR(__xludf.DUMMYFUNCTION("""COMPUTED_VALUE"""),"RTA") -> RTA | D22: =IFERROR(__xludf.DUMMYFUNCTION("""COMPUTED_VALUE"""),12.0) -> 12 | G22: =IFERROR(__xludf.DUMMYFUNCTION("""COMPUTED_VALUE"""),"DRS") -> DRS | H22: =IFERROR(__xludf.DUMMYFUNCTION("""COMPUTED_VALUE"""),"droneShop") -> droneShop | I22: =IFERROR(__xludf.DUMMYFUNCTION("""COMPUTED_VALUE"""),30.0) -> 30 | J22: =IFERROR(__xludf.DUMMYFUNCTION("""COMPUTED_VALUE"""),"ELECTRONICS") -> ELECTRONICS
A23: =IFERROR(__xludf.DUMMYFUNCTION("""COMPUTED_VALUE"""),"ACA-TRU") -> ACA-TRU | B23: =IFERROR(__xludf.DUMMYFUNCTION("""COMPUTED_VALUE"""),"ACA") -> ACA | C23: =IFERROR(__xludf.DUMMYFUNCTION("""COMPUTED_VALUE"""),"TRU") -> TRU | D23: =IFERROR(__xludf.DUMMYFUNCTION("""COMPUTED_VALUE"""),20.0) -> 20 | G23: =IFERROR(__xludf.DUMMYFUNCTION("""COMPUTED_VALUE"""),"ECA") -> ECA | H23: =IFERROR(__xludf.DUMMYFUNCTION("""COMPUTED_VALUE"""),"energyComponentAssembly") -> energyComponentAssembly | I23: =IFERROR(__xludf.DUMMYFUNCTION("""COMPUTED_VALUE"""),35.0) -> 35 | J23: =IFERROR(__xludf.DUMMYFUNCTION("""COMPUTED_VALUE"""),"ELECTRONICS") -> ELECTRONICS
A24: =IFERROR(__xludf.DUMMYFUNCTION("""COMPUTED_VALUE"""),"ADM-BMF") -> ADM-BMF | B24: =IFERROR(__xludf.DUMMYFUNCTION("""COMPUTED_VALUE"""),"ADM") -> ADM | C24: =IFERROR(__xludf.DUMMYFUNCTION("""COMPUTED_VALUE"""),"BMF") -> BMF | D24: =IFERROR(__xludf.DUMMYFUNCTION("""COMPUTED_VALUE"""),2.0) -> 2 | G24: =IFERROR(__xludf.DUMMYFUNCTION("""COMPUTED_VALUE"""),"EDM") -> EDM | H24: =IFERROR(__xludf.DUMMYFUNCTION("""COMPUTED_VALUE"""),"electronicDeviceManufactory") -> electronicDeviceManufactory | I24: =IFERROR(__xludf.DUMMYFUNCTION("""COMPUTED_VALUE"""),30.0) -> 30 | J24: =IFERROR(__xludf.DUMMYFUNCTION("""COMPUTED_VALUE"""),"ELECTRONICS") -> ELECTRONICS
A25: =IFERROR(__xludf.DUMMYFUNCTION("""COMPUTED_VALUE"""),"ADM-BWS") -> ADM-BWS | B25: =IFERROR(__xludf.DUMMYFUNCTION("""COMPUTED_VALUE"""),"ADM") -> ADM | C25: =IFERROR(__xludf.DUMMYFUNCTION("""COMPUTED_VALUE"""),"BWS") -> BWS | D25: =IFERROR(__xludf.DUMMYFUNCTION("""COMPUTED_VALUE"""),10.0) -> 10 | G25: =IFERROR(__xludf.DUMMYFUNCTION("""COMPUTED_VALUE"""),"EEP") -> EEP | H25: =IFERROR(__xludf.DUMMYFUNCTION("""COMPUTED_VALUE"""),"einsteiniumEnrichmentPlant") -> einsteiniumEnrichmentPlant | I25: =IFERROR(__xludf.DUMMYFUNCTION("""COMPUTED_VALUE"""),100.0) -> 100 | J25: =IFERROR(__xludf.DUMMYFUNCTION("""COMPUTED_VALUE"""),"CHEMISTRY") -> CHEMISTRY
A26: =IFERROR(__xludf.DUMMYFUNCTION("""COMPUTED_VALUE"""),"ADM-LBH") -> ADM-LBH | B26: =IFERROR(__xludf.DUMMYFUNCTION("""COMPUTED_VALUE"""),"ADM") -> ADM | C26: =IFERROR(__xludf.DUMMYFUNCTION("""COMPUTED_VALUE"""),"LBH") -> LBH | D26: =IFERROR(__xludf.DUMMYFUNCTION("""COMPUTED_VALUE"""),16.0) -> 16 | G26: =IFERROR(__xludf.DUMMYFUNCTION("""COMPUTED_VALUE"""),"ELP") -> ELP | H26: =IFERROR(__xludf.DUMMYFUNCTION("""COMPUTED_VALUE"""),"electronicsPlant") -> electronicsPlant | I26: =IFERROR(__xludf.DUMMYFUNCTION("""COMPUTED_VALUE"""),35.0) -> 35 | J26: =IFERROR(__xludf.DUMMYFUNCTION("""COMPUTED_VALUE"""),"ELECTRONICS") -> ELECTRONICS
A27: =IFERROR(__xludf.DUMMYFUNCTION("""COMPUTED_VALUE"""),"ADM-LDE") -> ADM-LDE | B27: =IFERROR(__xludf.DUMMYFUNCTION("""COMPUTED_VALUE"""),"ADM") -> ADM | C27: =IFERROR(__xludf.DUMMYFUNCTION("""COMPUTED_VALUE"""),"LDE") -> LDE | D27: =IFERROR(__xludf.DUMMYFUNCTION("""COMPUTED_VALUE"""),32.0) -> 32 | G27: =IFERROR(__xludf.DUMMYFUNCTION("""COMPUTED_VALUE"""),"EMC") -> EMC | H27: =IFERROR(__xludf.DUMMYFUNCTION("""COMPUTED_VALUE"""),"planetaryProjectSafetyHealth") -> planetaryProjectSafetyHealth | I27: =IFERROR(__xludf.DUMMYFUNCTION("""COMPUTED_VALUE"""),1000.0) -> 1000
A28: =IFERROR(__xludf.DUMMYFUNCTION("""COMPUTED_VALUE"""),"ADM-LSE") -> ADM-LSE | B28: =IFERROR(__xludf.DUMMYFUNCTION("""COMPUTED_VALUE"""),"ADM") -> ADM | C28: =IFERROR(__xludf.DUMMYFUNCTION("""COMPUTED_VALUE"""),"LSE") -> LSE | D28: =IFERROR(__xludf.DUMMYFUNCTION("""COMPUTED_VALUE"""),25.0) -> 25 | G28: =IFERROR(__xludf.DUMMYFUNCTION("""COMPUTED_VALUE"""),"EXT") -> EXT | H28: =IFERROR(__xludf.DUMMYFUNCTION("""COMPUTED_VALUE"""),"extractor") -> extractor | I28: =IFERROR(__xludf.DUMMYFUNCTION("""COMPUTED_VALUE"""),25.0) -> 25 | J28: =IFERROR(__xludf.DUMMYFUNCTION("""COMPUTED_VALUE"""),"RESOURCE_EXTRACTION") -> RESOURCE_EXTRACTION
A29: =IFERROR(__xludf.DUMMYFUNCTION("""COMPUTED_VALUE"""),"ADM-MCG") -> ADM-MCG | B29: =IFERROR(__xludf.DUMMYFUNCTION("""COMPUTED_VALUE"""),"ADM") -> ADM | C29: =IFERROR(__xludf.DUMMYFUNCTION("""COMPUTED_VALUE"""),"MCG") -> MCG | D29: =IFERROR(__xludf.DUMMYFUNCTION("""COMPUTED_VALUE"""),750.0) -> 750 | G29: =IFERROR(__xludf.DUMMYFUNCTION("""COMPUTED_VALUE"""),"FER") -> FER | H29: =IFERROR(__xludf.DUMMYFUNCTION("""COMPUTED_VALUE"""),"fermentationFacility") -> fermentationFacility | I29: =IFERROR(__xludf.DUMMYFUNCTION("""COMPUTED_VALUE"""),25.0) -> 25 | J29: =IFERROR(__xludf.DUMMYFUNCTION("""COMPUTED_VALUE"""),"FOOD_INDUSTRIES") -> FOOD_INDUSTRIES
A30: =IFERROR(__xludf.DUMMYFUNCTION("""COMPUTED_VALUE"""),"ADM-RTA") -> ADM-RTA | B30: =IFERROR(__xludf.DUMMYFUNCTION("""COMPUTED_VALUE"""),"ADM") -> ADM | C30: =IFERROR(__xludf.DUMMYFUNCTION("""COMPUTED_VALUE"""),"RTA") -> RTA | D30: =IFERROR(__xludf.DUMMYFUNCTION("""COMPUTED_VALUE"""),5.0) -> 5 | G30: =IFERROR(__xludf.DUMMYFUNCTION("""COMPUTED_VALUE"""),"FP") -> FP | H30: =IFERROR(__xludf.DUMMYFUNCTION("""COMPUTED_VALUE"""),"foodProcessor") -> foodProcessor | I30: =IFERROR(__xludf.DUMMYFUNCTION("""COMPUTED_VALUE"""),12.0) -> 12 | J30: =IFERROR(__xludf.DUMMYFUNCTION("""COMPUTED_VALUE"""),"FOOD_INDUSTRIES") -> FOOD_INDUSTRIES
A31: =IFERROR(__xludf.DUMMYFUNCTION("""COMPUTED_VALUE"""),"AML-ABH") -> AML-ABH | B31: =IFERROR(__xludf.DUMMYFUNCTION("""COMPUTED_VALUE"""),"AML") -> AML | C31: =IFERROR(__xludf.DUMMYFUNCTION("""COMPUTED_VALUE"""),"ABH") -> ABH | D31: =IFERROR(__xludf.DUMMYFUNCTION("""COMPUTED_VALUE"""),10.0) -> 10 | G31: =IFERROR(__xludf.DUMMYFUNCTION("""COMPUTED_VALUE"""),"FRM") -> FRM | H31: =IFERROR(__xludf.DUMMYFUNCTION("""COMPUTED_VALUE"""),"farm") -> farm | I31: =IFERROR(__xludf.DUMMYFUNCTION("""COMPUTED_VALUE"""),30.0) -> 30 | J31: =IFERROR(__xludf.DUMMYFUNCTION("""COMPUTED_VALUE"""),"AGRICULTURE") -> AGRICULTURE
A32: =IFERROR(__xludf.DUMMYFUNCTION("""COMPUTED_VALUE"""),"AML-ADE") -> AML-ADE | B32: =IFERROR(__xludf.DUMMYFUNCTION("""COMPUTED_VALUE"""),"AML") -> AML | C32: =IFERROR(__xludf.DUMMYFUNCTION("""COMPUTED_VALUE"""),"ADE") -> ADE | D32: =IFERROR(__xludf.DUMMYFUNCTION("""COMPUTED_VALUE"""),6.0) -> 6 | G32: =IFERROR(__xludf.DUMMYFUNCTION("""COMPUTED_VALUE"""),"FS") -> FS | H32: =IFERROR(__xludf.DUMMYFUNCTION("""COMPUTED_VALUE"""),"fineSmithy") -> fineSmithy | I32: =IFERROR(__xludf.DUMMYFUNCTION("""COMPUTED_VALUE"""),25.0) -> 25 | J32: =IFERROR(__xludf.DUMMYFUNCTION("""COMPUTED_VALUE"""),"METALLURGY") -> METALLURGY
A33: =IFERROR(__xludf.DUMMYFUNCTION("""COMPUTED_VALUE"""),"AML-ASE") -> AML-ASE | B33: =IFERROR(__xludf.DUMMYFUNCTION("""COMPUTED_VALUE"""),"AML") -> AML | C33: =IFERROR(__xludf.DUMMYFUNCTION("""COMPUTED_VALUE"""),"ASE") -> ASE | D33: =IFERROR(__xludf.DUMMYFUNCTION("""COMPUTED_VALUE"""),6.0) -> 6 | G33: =IFERROR(__xludf.DUMMYFUNCTION("""COMPUTED_VALUE"""),"GF") -> GF | H33: =IFERROR(__xludf.DUMMYFUNCTION("""COMPUTED_VALUE"""),"glassFurnace") -> glassFurnace | I33: =IFERROR(__xludf.DUMMYFUNCTION("""COMPUTED_VALUE"""),27.0) -> 27 | J33: =IFERROR(__xludf.DUMMYFUNCTION("""COMPUTED_VALUE"""),"METALLURGY") -> METALLURGY
A34: =IFERROR(__xludf.DUMMYFUNCTION("""COMPUTED_VALUE"""),"AML-TRU") -> AML-TRU | B34: =IFERROR(__xludf.DUMMYFUNCTION("""COMPUTED_VALUE"""),"AML") -> AML | C34: =IFERROR(__xludf.DUMMYFUNCTION("""COMPUTED_VALUE"""),"TRU") -> TRU | D34: =IFERROR(__xludf.DUMMYFUNCTION("""COMPUTED_VALUE"""),6.0) -> 6 | G34: =IFERROR(__xludf.DUMMYFUNCTION("""COMPUTED_VALUE"""),"HB1") -> HB1 | H34: =IFERROR(__xludf.DUMMYFUNCTION("""COMPUTED_VALUE"""),"habitationPioneer") -> habitationPioneer | I34: =IFERROR(__xludf.DUMMYFUNCTION("""COMPUTED_VALUE"""),10.0) -> 10
A35: =IFERROR(__xludf.DUMMYFUNCTION("""COMPUTED_VALUE"""),"APF-ABH") -> APF-ABH | B35: =IFERROR(__xludf.DUMMYFUNCTION("""COMPUTED_VALUE"""),"APF") -> APF | C35: =IFERROR(__xludf.DUMMYFUNCTION("""COMPUTED_VALUE"""),"ABH") -> ABH | D35: =IFERROR(__xludf.DUMMYFUNCTION("""COMPUTED_VALUE"""),6.0) -> 6 | G35: =IFERROR(__xludf.DUMMYFUNCTION("""COMPUTED_VALUE"""),"HB2") -> HB2 | H35: =IFERROR(__xludf.DUMMYFUNCTION("""COMPUTED_VALUE"""),"habitationSettler") -> habitationSettler | I35: =IFERROR(__xludf.DUMMYFUNCTION("""COMPUTED_VALUE"""),12.0) -> 12
A36: =IFERROR(__xludf.DUMMYFUNCTION("""COMPUTED_VALUE"""),"APF-ADE") -> APF-ADE | B36: =IFERROR(__xludf.DUMMYFUNCTION("""COMPUTED_VALUE"""),"APF") -> APF | C36: =IFERROR(__xludf.DUMMYFUNCTION("""COMPUTED_VALUE"""),"ADE") -> ADE | D36: =IFERROR(__xludf.DUMMYFUNCTION("""COMPUTED_VALUE"""),10.0) -> 10 | G36: =IFERROR(__xludf.DUMMYFUNCTION("""COMPUTED_VALUE"""),"HB3") -> HB3 | H36: =IFERROR(__xludf.DUMMYFUNCTION("""COMPUTED_VALUE"""),"habitationTechnician") -> habitationTechnician | I36: =IFERROR(__xludf.DUMMYFUNCTION("""COMPUTED_VALUE"""),14.0) -> 14
A37: =IFERROR(__xludf.DUMMYFUNCTION("""COMPUTED_VALUE"""),"APF-ASE") -> APF-ASE | B37: =IFERROR(__xludf.DUMMYFUNCTION("""COMPUTED_VALUE"""),"APF") -> APF | C37: =IFERROR(__xludf.DUMMYFUNCTION("""COMPUTED_VALUE"""),"ASE") -> ASE | D37: =IFERROR(__xludf.DUMMYFUNCTION("""COMPUTED_VALUE"""),10.0) -> 10 | G37: =IFERROR(__xludf.DUMMYFUNCTION("""COMPUTED_VALUE"""),"HB4") -> HB4 | H37: =IFERROR(__xludf.DUMMYFUNCTION("""COMPUTED_VALUE"""),"habitationEngineer") -> habitationEngineer | I37: =IFERROR(__xludf.DUMMYFUNCTION("""COMPUTED_VALUE"""),16.0) -> 16
A38: =IFERROR(__xludf.DUMMYFUNCTION("""COMPUTED_VALUE"""),"APF-TRU") -> APF-TRU | B38: =IFERROR(__xludf.DUMMYFUNCTION("""COMPUTED_VALUE"""),"APF") -> APF | C38: =IFERROR(__xludf.DUMMYFUNCTION("""COMPUTED_VALUE"""),"TRU") -> TRU | D38: =IFERROR(__xludf.DUMMYFUNCTION("""COMPUTED_VALUE"""),8.0) -> 8 | G38: =IFERROR(__xludf.DUMMYFUNCTION("""COMPUTED_VALUE"""),"HB5") -> HB5 | H38: =IFERROR(__xludf.DUMMYFUNCTION("""COMPUTED_VALUE"""),"habitationScientist") -> habitationScientist | I38: =IFERROR(__xludf.DUMMYFUNCTION("""COMPUTED_VALUE"""),18.0) -> 18
A39: =IFERROR(__xludf.DUMMYFUNCTION("""COMPUTED_VALUE"""),"ART-DEC") -> ART-DEC | B39: =IFERROR(__xludf.DUMMYFUNCTION("""COMPUTED_VALUE"""),"ART") -> ART | C39: =IFERROR(__xludf.DUMMYFUNCTION("""COMPUTED_VALUE"""),"DEC") -> DEC | D39: =IFERROR(__xludf.DUMMYFUNCTION("""COMPUTED_VALUE"""),10.0) -> 10 | G39: =IFERROR(__xludf.DUMMYFUNCTION("""COMPUTED_VALUE"""),"HBB") -> HBB | H39: =IFERROR(__xludf.DUMMYFUNCTION("""COMPUTED_VALUE"""),"habitationBarracks") -> habitationBarracks | I39: =IFERROR(__xludf.DUMMYFUNCTION("""COMPUTED_VALUE"""),14.0) -> 14
A40: =IFERROR(__xludf.DUMMYFUNCTION("""COMPUTED_VALUE"""),"ART-LBH") -> ART-LBH | B40: =IFERROR(__xludf.DUMMYFUNCTION("""COMPUTED_VALUE"""),"ART") -> ART | C40: =IFERROR(__xludf.DUMMYFUNCTION("""COMPUTED_VALUE"""),"LBH") -> LBH | D40: =IFERROR(__xludf.DUMMYFUNCTION("""COMPUTED_VALUE"""),24.0) -> 24 | G40: =IFERROR(__xludf.DUMMYFUNCTION("""COMPUTED_VALUE"""),"HBC") -> HBC | H40: =IFERROR(__xludf.DUMMYFUNCTION("""COMPUTED_VALUE"""),"habitationCommune") -> habitationCommune | I40: =IFERROR(__xludf.DUMMYFUNCTION("""COMPUTED_VALUE"""),17.0) -> 17
...

Sheet CXP
A1: =IFERROR(__xludf.DUMMYFUNCTION("IMPORTDATA(""https://rest.fnar.net/csv/prices"")"),"Ticker") -> Ticker | B1: =IFERROR(__xludf.DUMMYFUNCTION("""COMPUTED_VALUE"""),"MMBuy") -> MMBuy | C1: =IFERROR(__xludf.DUMMYFUNCTION("""COMPUTED_VALUE"""),"MMSell") -> MMSell | D1: =IFERROR(__xludf.DUMMYFUNCTION("""COMPUTED_VALUE"""),"AI1-Average") -> AI1-Average | E1: =IFERROR(__xludf.DUMMYFUNCTION("""COMPUTED_VALUE"""),"AI1-AskAmt") -> AI1-AskAmt | F1: =IFERROR(__xludf.DUMMYFUNCTION("""COMPUTED_VALUE"""),"AI1-AskPrice") -> AI1-AskPrice | G1: =IFERROR(__xludf.DUMMYFUNCTION("""COMPUTED_VALUE"""),"AI1-AskAvail") -> AI1-AskAvail | H1: =IFERROR(__xludf.DUMMYFUNCTION("""COMPUTED_VALUE"""),"AI1-BidAmt") -> AI1-BidAmt | I1: =IFERROR(__xludf.DUMMYFUNCTION("""COMPUTED_VALUE"""),"AI1-BidPrice") -> AI1-BidPrice | J1: =IFERROR(__xludf.DUMMYFUNCTION("""COMPUTED_VALUE"""),"AI1-BidAvail") -> AI1-BidAvail | K1: =IFERROR(__xludf.DUMMYFUNCTION("""COMPUTED_VALUE"""),"CI1-Average") -> CI1-Average | L1: =IFERROR(__xludf.DUMMYFUNCTION("""COMPUTED_VALUE"""),"CI1-AskAmt") -> CI1-AskAmt | M1: =IFERROR(__xludf.DUMMYFUNCTION("""COMPUTED_VALUE"""),"CI1-AskPrice") -> CI1-AskPrice | N1: =IFERROR(__xludf.DUMMYFUNCTION("""COMPUTED_VALUE"""),"CI1-AskAvail") -> CI1-AskAvail | O1: =IFERROR(__xludf.DUMMYFUNCTION("""COMPUTED_VALUE"""),"CI1-BidAmt") -> CI1-BidAmt | P1: =IFERROR(__xludf.DUMMYFUNCTION("""COMPUTED_VALUE"""),"CI1-BidPrice") -> CI1-BidPrice | Q1: =IFERROR(__xludf.DUMMYFUNCTION("""COMPUTED_VALUE"""),"CI1-BidAvail") -> CI1-BidAvail | R1: =IFERROR(__xludf.DUMMYFUNCTION("""COMPUTED_VALUE"""),"CI2-Average") -> CI2-Average | S1: =IFERROR(__xludf.DUMMYFUNCTION("""COMPUTED_VALUE"""),"CI2-AskAmt") -> CI2-AskAmt | T1: =IFERROR(__xludf.DUMMYFUNCTION("""COMPUTED_VALUE"""),"CI2-AskPrice") -> CI2-AskPrice | U1: =IFERROR(__xludf.DUMMYFUNCTION("""COMPUTED_VALUE"""),"CI2-AskAvail") -> CI2-AskAvail | V1: =IFERROR(__xludf.DUMMYFUNCTION("""COMPUTED_VALUE"""),"CI2-BidAmt") -> CI2-BidAmt | W1: =IFERROR(__xludf.DUMMYFUNCTION("""COMPUTED_VALUE"""),"CI2-BidPrice") -> CI2-BidPrice | X1: =IFERROR(__xludf.DUMMYFUNCTION("""COMPUTED_VALUE"""),"CI2-BidAvail") -> CI2-BidAvail | Y1: =IFERROR(__xludf.DUMMYFUNCTION("""COMPUTED_VALUE"""),"NC1-Average") -> NC1-Average | Z1: =IFERROR(__xludf.DUMMYFUNCTION("""COMPUTED_VALUE"""),"NC1-AskAmt") -> NC1-AskAmt | AA1: =IFERROR(__xludf.DUMMYFUNCTION("""COMPUTED_VALUE"""),"NC1-AskPrice") -> NC1-AskPrice | AB1: =IFERROR(__xludf.DUMMYFUNCTION("""COMPUTED_VALUE"""),"NC1-AskAvail") -> NC1-AskAvail | AC1: =IFERROR(__xludf.DUMMYFUNCTION("""COMPUTED_VALUE"""),"NC1-BidAmt") -> NC1-BidAmt | AD1: =IFERROR(__xludf.DUMMYFUNCTION("""COMPUTED_VALUE"""),"NC1-BidPrice") -> NC1-BidPrice | AE1: =IFERROR(__xludf.DUMMYFUNCTION("""COMPUTED_VALUE"""),"NC1-BidAvail") -> NC1-BidAvail | AF1: =IFERROR(__xludf.DUMMYFUNCTION("""COMPUTED_VALUE"""),"NC2-Average") -> NC2-Average | AG1: =IFERROR(__xludf.DUMMYFUNCTION("""COMPUTED_VALUE"""),"NC2-AskAmt") -> NC2-AskAmt | AH1: =IFERROR(__xludf.DUMMYFUNCTION("""COMPUTED_VALUE"""),"NC2-AskPrice") -> NC2-AskPrice | AI1: =IFERROR(__xludf.DUMMYFUNCTION("""COMPUTED_VALUE"""),"NC2-AskAvail") -> NC2-AskAvail | AJ1: =IFERROR(__xludf.DUMMYFUNCTION("""COMPUTED_VALUE"""),"NC2-BidAmt") -> NC2-BidAmt | AK1: =IFERROR(__xludf.DUMMYFUNCTION("""COMPUTED_VALUE"""),"NC2-BidPrice") -> NC2-BidPrice | AL1: =IFERROR(__xludf.DUMMYFUNCTION("""COMPUTED_VALUE"""),"NC2-BidAvail") -> NC2-BidAvail | AM1: =IFERROR(__xludf.DUMMYFUNCTION("""COMPUTED_VALUE"""),"IC1-Average") -> IC1-Average | AN1: =IFERROR(__xludf.DUMMYFUNCTION("""COMPUTED_VALUE"""),"IC1-AskAmt") -> IC1-AskAmt | AO1: =IFERROR(__xludf.DUMMYFUNCTION("""COMPUTED_VALUE"""),"IC1-AskPrice") -> IC1-AskPrice | AP1: =IFERROR(__xludf.DUMMYFUNCTION("""COMPUTED_VALUE"""),"IC1-AskAvail") -> IC1-AskAvail | AQ1: =IFERROR(__xludf.DUMMYFUNCTION("""COMPUTED_VALUE"""),"IC1-BidAmt") -> IC1-BidAmt | AR1: =IFERROR(__xludf.DUMMYFUNCTION("""COMPUTED_VALUE"""),"IC1-BidPrice") -> IC1-BidPrice | AS1: =IFERROR(__xludf.DUMMYFUNCTION("""COMPUTED_VALUE"""),"IC1-BidAvail") -> IC1-BidAvail
A2: =IFERROR(__xludf.DUMMYFUNCTION("""COMPUTED_VALUE"""),"AAR") -> AAR | D2: =IFERROR(__xludf.DUMMYFUNCTION("""COMPUTED_VALUE"""),16000.0) -> 16000 | E2: =IFERROR(__xludf.DUMMYFUNCTION("""COMPUTED_VALUE"""),119.0) -> 119 | F2: =IFERROR(__xludf.DUMMYFUNCTION("""COMPUTED_VALUE"""),16000.0) -> 16000 | G2: =IFERROR(__xludf.DUMMYFUNCTION("""COMPUTED_VALUE"""),1082.0) -> 1082 | H2: =IFERROR(__xludf.DUMMYFUNCTION("""COMPUTED_VALUE"""),7.0) -> 7 | I2: =IFERROR(__xludf.DUMMYFUNCTION("""COMPUTED_VALUE"""),15100.0) -> 15100 | J2: =IFERROR(__xludf.DUMMYFUNCTION("""COMPUTED_VALUE"""),159.0) -> 159 | K2: =IFERROR(__xludf.DUMMYFUNCTION("""COMPUTED_VALUE"""),15000.0) -> 15000 | L2: =IFERROR(__xludf.DUMMYFUNCTION("""COMPUTED_VALUE"""),279.0) -> 279 | M2: =IFERROR(__xludf.DUMMYFUNCTION("""COMPUTED_VALUE"""),15000.0) -> 15000 | N2: =IFERROR(__xludf.DUMMYFUNCTION("""COMPUTED_VALUE"""),292.0) -> 292 | O2: =IFERROR(__xludf.DUMMYFUNCTION("""COMPUTED_VALUE"""),200.0) -> 200 | P2: =IFERROR(__xludf.DUMMYFUNCTION("""COMPUTED_VALUE"""),14100.0) -> 14100 | Q2: =IFERROR(__xludf.DUMMYFUNCTION("""COMPUTED_VALUE"""),300.0) -> 300 | R2: =IFERROR(__xludf.DUMMYFUNCTION("""COMPUTED_VALUE"""),20000.0) -> 20000 | U2: =IFERROR(__xludf.DUMMYFUNCTION("""COMPUTED_VALUE"""),0.0) -> 0 | X2: =IFERROR(__xludf.DUMMYFUNCTION("""COMPUTED_VALUE"""),0.0) -> 0 | Y2: =IFERROR(__xludf.DUMMYFUNCTION("""COMPUTED_VALUE"""),15900.0) -> 15900 | Z2: =IFERROR(__xludf.DUMMYFUNCTION("""COMPUTED_VALUE"""),19.0) -> 19 | AA2: =IFERROR(__xludf.DUMMYFUNCTION("""COMPUTED_VALUE"""),15900.0) -> 15900 | AB2: =IFERROR(__xludf.DUMMYFUNCTION("""COMPUTED_VALUE"""),1460.0) -> 1460 | AC2: =IFERROR(__xludf.DUMMYFUNCTION("""COMPUTED_VALUE"""),21.0) -> 21 | AD2: =IFERROR(__xludf.DUMMYFUNCTION("""COMPUTED_VALUE"""),14300.0) -> 14300 | AE2: =IFERROR(__xludf.DUMMYFUNCTION("""COMPUTED_VALUE"""),148.0) -> 148 | AF2: =IFERROR(__xludf.DUMMYFUNCTION("""COMPUTED_VALUE"""),6765.330078125) -> 6765.3301 | AG2: =IFERROR(__xludf.DUMMYFUNCTION("""COMPUTED_VALUE"""),3.0) -> 3 | AH2: =IFERROR(__xludf.DUMMYFUNCTION("""COMPUTED_VALUE"""),16200.0) -> 16200 | AI2: =IFERROR(__xludf.DUMMYFUNCTION("""COMPUTED_VALUE"""),3.0) -> 3 | AL2: =IFERROR(__xludf.DUMMYFUNCTION("""COMPUTED_VALUE"""),0.0) -> 0 | AM2: =IFERROR(__xludf.DUMMYFUNCTION("""COMPUTED_VALUE"""),14800.0) -> 14800 | AN2: =IFERROR(__xludf.DUMMYFUNCTION("""COMPUTED_VALUE"""),19.0) -> 19 | AO2: =IFERROR(__xludf.DUMMYFUNCTION("""COMPUTED_VALUE"""),14800.0) -> 14800 | AP2: =IFERROR(__xludf.DUMMYFUNCTION("""COMPUTED_VALUE"""),19.0) -> 19 | AQ2: =IFERROR(__xludf.DUMMYFUNCTION("""COMPUTED_VALUE"""),200.0) -> 200 | AR2: =IFERROR(__xludf.DUMMYFUNCTION("""COMPUTED_VALUE"""),14100.0) -> 14100 | AS2: =IFERROR(__xludf.DUMMYFUNCTION("""COMPUTED_VALUE"""),300.0) -> 300
A3: =IFERROR(__xludf.DUMMYFUNCTION("""COMPUTED_VALUE"""),"ABH") -> ABH | D3: =IFERROR(__xludf.DUMMYFUNCTION("""COMPUTED_VALUE"""),47200.0) -> 47200 | E3: =IFERROR(__xludf.DUMMYFUNCTION("""COMPUTED_VALUE"""),10.0) -> 10 | F3: =IFERROR(__xludf.DUMMYFUNCTION("""COMPUTED_VALUE"""),58000.0) -> 58000 | G3: =IFERROR(__xludf.DUMMYFUNCTION("""COMPUTED_VALUE"""),526.0) -> 526 | H3: =IFERROR(__xludf.DUMMYFUNCTION("""COMPUTED_VALUE"""),20.0) -> 20 | I3: =IFERROR(__xludf.DUMMYFUNCTION("""COMPUTED_VALUE"""),47200.0) -> 47200 | J3: =IFERROR(__xludf.DUMMYFUNCTION("""COMPUTED_VALUE"""),1155.0) -> 1155 | K3: =IFERROR(__xludf.DUMMYFUNCTION("""COMPUTED_VALUE"""),47800.0) -> 47800 | L3: =IFERROR(__xludf.DUMMYFUNCTION("""COMPUTED_VALUE"""),72.0) -> 72 | M3: =IFERROR(__xludf.DUMMYFUNCTION("""COMPUTED_VALUE"""),48700.0) -> 48700 | N3: =IFERROR(__xludf.DUMMYFUNCTION("""COMPUTED_VALUE"""),336.0) -> 336 | O3: =IFERROR(__xludf.DUMMYFUNCTION("""COMPUTED_VALUE"""),174.0) -> 174 | P3: =IFERROR(__xludf.DUMMYFUNCTION("""COMPUTED_VALUE"""),47800.0) -> 47800 | Q3: =IFERROR(__xludf.DUMMYFUNCTION("""COMPUTED_VALUE"""),719.0) -> 719 | R3: =IFERROR(__xludf.DUMMYFUNCTION("""COMPUTED_VALUE"""),46000.0) -> 46000 | U3: =IFERROR(__xludf.DUMMYFUNCTION("""COMPUTED_VALUE"""),0.0) -> 0 | X3: =IFERROR(__xludf.DUMMYFUNCTION("""COMPUTED_VALUE"""),0.0) -> 0 | Y3: =IFERROR(__xludf.DUMMYFUNCTION("""COMPUTED_VALUE"""),46100.0) -> 46100 | Z3: =IFERROR(__xludf.DUMMYFUNCTION("""COMPUTED_VALUE"""),28.0) -> 28 | AA3: =IFERROR(__xludf.DUMMYFUNCTION("""COMPUTED_VALUE"""),51000.0) -> 51000 | AB3: =IFERROR(__xludf.DUMMYFUNCTION("""COMPUTED_VALUE"""),896.0) -> 896 | AC3: =IFERROR(__xludf.DUMMYFUNCTION("""COMPUTED_VALUE"""),8.0) -> 8 | AD3: =IFERROR(__xludf.DUMMYFUNCTION("""COMPUTED_VALUE"""),46100.0) -> 46100 | AE3: =IFERROR(__xludf.DUMMYFUNCTION("""COMPUTED_VALUE"""),1148.0) -> 1148 | AF3: =IFERROR(__xludf.DUMMYFUNCTION("""COMPUTED_VALUE"""),24074.48046875) -> 24074.48 | AG3: =IFERROR(__xludf.DUMMYFUNCTION("""COMPUTED_VALUE"""),5.0) -> 5 | AH3: =IFERROR(__xludf.DUMMYFUNCTION("""COMPUTED_VALUE"""),60000.0) -> 60000 | AI3: =IFERROR(__xludf.DUMMYFUNCTION("""COMPUTED_VALUE"""),5.0) -> 5 | AL3: =IFERROR(__xludf.DUMMYFUNCTION("""COMPUTED_VALUE"""),0.0) -> 0 | AM3: =IFERROR(__xludf.DUMMYFUNCTION("""COMPUTED_VALUE"""),59797.73828125) -> 59797.738 | AP3: =IFERROR(__xludf.DUMMYFUNCTION("""COMPUTED_VALUE"""),0.0) -> 0 | AQ3: =IFERROR(__xludf.DUMMYFUNCTION("""COMPUTED_VALUE"""),86.0) -> 86 | AR3: =IFERROR(__xludf.DUMMYFUNCTION("""COMPUTED_VALUE"""),42300.0) -> 42300 | AS3: =IFERROR(__xludf.DUMMYFUNCTION("""COMPUTED_VALUE"""),423.0) -> 423
A4: =IFERROR(__xludf.DUMMYFUNCTION("""COMPUTED_VALUE"""),"ACS") -> ACS | D4: =IFERROR(__xludf.DUMMYFUNCTION("""COMPUTED_VALUE"""),175000.0) -> 175000 | E4: =IFERROR(__xludf.DUMMYFUNCTION("""COMPUTED_VALUE"""),7.0) -> 7 | F4: =IFERROR(__xludf.DUMMYFUNCTION("""COMPUTED_VALUE"""),170000.0) -> 170000 | G4: =IFERROR(__xludf.DUMMYFUNCTION("""COMPUTED_VALUE"""),37.0) -> 37 | H4: =IFERROR(__xludf.DUMMYFUNCTION("""COMPUTED_VALUE"""),5.0) -> 5 | I4: =IFERROR(__xludf.DUMMYFUNCTION("""COMPUTED_VALUE"""),141000.0) -> 141000 | J4: =IFERROR(__xludf.DUMMYFUNCTION("""COMPUTED_VALUE"""),53.0) -> 53 | K4: =IFERROR(__xludf.DUMMYFUNCTION("""COMPUTED_VALUE"""),160000.0) -> 160000 | L4: =IFERROR(__xludf.DUMMYFUNCTION("""COMPUTED_VALUE"""),1.0) -> 1 | M4: =IFERROR(__xludf.DUMMYFUNCTION("""COMPUTED_VALUE"""),180000.0) -> 180000 | N4: =IFERROR(__xludf.DUMMYFUNCTION("""COMPUTED_VALUE"""),1.0) -> 1 | O4: =IFERROR(__xludf.DUMMYFUNCTION("""COMPUTED_VALUE"""),1.0) -> 1 | P4: =IFERROR(__xludf.DUMMYFUNCTION("""COMPUTED_VALUE"""),150000.0) -> 150000 | Q4: =IFERROR(__xludf.DUMMYFUNCTION("""COMPUTED_VALUE"""),4.0) -> 4 | R4: =IFERROR(__xludf.DUMMYFUNCTION("""COMPUTED_VALUE"""),74556.703125) -> 74556.703 | U4: =IFERROR(__xludf.DUMMYFUNCTION("""COMPUTED_VALUE"""),0.0) -> 0 | X4: =IFERROR(__xludf.DUMMYFUNCTION("""COMPUTED_VALUE"""),0.0) -> 0 | Y4: =IFERROR(__xludf.DUMMYFUNCTION("""COMPUTED_VALUE"""),150000.0) -> 150000 | Z4: =IFERROR(__xludf.DUMMYFUNCTION("""COMPUTED_VALUE"""),1.0) -> 1 | AA4: =IFERROR(__xludf.DUMMYFUNCTION("""COMPUTED_VALUE"""),170000.0) -> 170000 | AB4: =IFERROR(__xludf.DUMMYFUNCTION("""COMPUTED_VALUE"""),1.0) -> 1 | AC4: =IFERROR(__xludf.DUMMYFUNCTION("""COMPUTED_VALUE"""),1.0) -> 1 | AD4: =IFERROR(__xludf.DUMMYFUNCTION("""COMPUTED_VALUE"""),160000.0) -> 160000 | AE4: =IFERROR(__xludf.DUMMYFUNCTION("""COMPUTED_VALUE"""),24.0) -> 24 | AF4: =IFERROR(__xludf.DUMMYFUNCTION("""COMPUTED_VALUE"""),74556.703125) -> 74556.703 | AG4: =IFERROR(__xludf.DUMMYFUNCTION("""COMPUTED_VALUE"""),1.0) -> 1 | AH4: =IFERROR(__xludf.DUMMYFUNCTION("""COMPUTED_VALUE"""),124000.0) -> 124000 | AI4: =IFERROR(__xludf.DUMMYFUNCTION("""COMPUTED_VALUE"""),1.0) -> 1 | AL4: =IFERROR(__xludf.DUMMYFUNCTION("""COMPUTED_VALUE"""),0.0) -> 0 | AM4: =IFERROR(__xludf.DUMMYFUNCTION("""COMPUTED_VALUE"""),140000.0) -> 140000 | AP4: =IFERROR(__xludf.DUMMYFUNCTION("""COMPUTED_VALUE"""),0.0) -> 0 | AS4: =IFERROR(__xludf.DUMMYFUNCTION("""COMPUTED_VALUE"""),0.0) -> 0
A5: =IFERROR(__xludf.DUMMYFUNCTION("""COMPUTED_VALUE"""),"ADE") -> ADE | D5: =IFERROR(__xludf.DUMMYFUNCTION("""COMPUTED_VALUE"""),40561.25) -> 40561.25 | E5: =IFERROR(__xludf.DUMMYFUNCTION("""COMPUTED_VALUE"""),30.0) -> 30 | F5: =IFERROR(__xludf.DUMMYFUNCTION("""COMPUTED_VALUE"""),53800.0) -> 53800 | G5: =IFERROR(__xludf.DUMMYFUNCTION("""COMPUTED_VALUE"""),573.0) -> 573 | H5: =IFERROR(__xludf.DUMMYFUNCTION("""COMPUTED_VALUE"""),189.0) -> 189 | I5: =IFERROR(__xludf.DUMMYFUNCTION("""COMPUTED_VALUE"""),40500.0) -> 40500 | J5: =IFERROR(__xludf.DUMMYFUNCTION("""COMPUTED_VALUE"""),289.0) -> 289 | K5: =IFERROR(__xludf.DUMMYFUNCTION("""COMPUTED_VALUE"""),42200.0) -> 42200 | L5: =IFERROR(__xludf.DUMMYFUNCTION("""COMPUTED_VALUE"""),40.0) -> 40 | M5: =IFERROR(__xludf.DUMMYFUNCTION("""COMPUTED_VALUE"""),44900.0) -> 44900 | N5: =IFERROR(__xludf.DUMMYFUNCTION("""COMPUTED_VALUE"""),241.0) -> 241 | O5: =IFERROR(__xludf.DUMMYFUNCTION("""COMPUTED_VALUE"""),112.0) -> 112 | P5: =IFERROR(__xludf.DUMMYFUNCTION("""COMPUTED_VALUE"""),42200.0) -> 42200 | Q5: =IFERROR(__xludf.DUMMYFUNCTION("""COMPUTED_VALUE"""),508.0) -> 508 | R5: =IFERROR(__xludf.DUMMYFUNCTION("""COMPUTED_VALUE"""),43000.0) -> 43000 | U5: =IFERROR(__xludf.DUMMYFUNCTION("""COMPUTED_VALUE"""),0.0) -> 0 | X5: =IFERROR(__xludf.DUMMYFUNCTION("""COMPUTED_VALUE"""),0.0) -> 0 | Y5: =IFERROR(__xludf.DUMMYFUNCTION("""COMPUTED_VALUE"""),46900.0) -> 46900 | Z5: =IFERROR(__xludf.DUMMYFUNCTION("""COMPUTED_VALUE"""),4.0) -> 4 | AA5: =IFERROR(__xludf.DUMMYFUNCTION("""COMPUTED_VALUE"""),48100.0) -> 48100 | AB5: =IFERROR(__xludf.DUMMYFUNCTION("""COMPUTED_VALUE"""),699.0) -> 699 | AC5: =IFERROR(__xludf.DUMMYFUNCTION("""COMPUTED_VALUE"""),50.0) -> 50 | AD5: =IFERROR(__xludf.DUMMYFUNCTION("""COMPUTED_VALUE"""),41900.0) -> 41900 | AE5: =IFERROR(__xludf.DUMMYFUNCTION("""COMPUTED_VALUE"""),611.0) -> 611 | AF5: =IFERROR(__xludf.DUMMYFUNCTION("""COMPUTED_VALUE"""),21210.509765625) -> 21210.51 | AG5: =IFERROR(__xludf.DUMMYFUNCTION("""COMPUTED_VALUE"""),7.0) -> 7 | AH5: =IFERROR(__xludf.DUMMYFUNCTION("""COMPUTED_VALUE"""),60000.0) -> 60000 | AI5: =IFERROR(__xludf.DUMMYFUNCTION("""COMPUTED_VALUE"""),7.0) -> 7 | AL5: =IFERROR(__xludf.DUMMYFUNCTION("""COMPUTED_VALUE"""),0.0) -> 0 | AM5: =IFERROR(__xludf.DUMMYFUNCTION("""COMPUTED_VALUE"""),48471.2109375) -> 48471.211 | AN5: =IFERROR(__xludf.DUMMYFUNCTION("""COMPUTED_VALUE"""),28.0) -> 28 | AO5: =IFERROR(__xludf.DUMMYFUNCTION("""COMPUTED_VALUE"""),48500.0) -> 48500 | AP5: =IFERROR(__xludf.DUMMYFUNCTION("""COMPUTED_VALUE"""),530.0) -> 530 | AQ5: =IFERROR(__xludf.DUMMYFUNCTION("""COMPUTED_VALUE"""),30.0) -> 30 | AR5: =IFERROR(__xludf.DUMMYFUNCTION("""COMPUTED_VALUE"""),37000.0) -> 37000 | AS5: =IFERROR(__xludf.DUMMYFUNCTION("""COMPUTED_VALUE"""),209.0) -> 209
A6: =IFERROR(__xludf.DUMMYFUNCTION("""COMPUTED_VALUE"""),"ADR") -> ADR | B6: =IFERROR(__xludf.DUMMYFUNCTION("""COMPUTED_VALUE"""),70000.0) -> 70000 | D6: =IFERROR(__xludf.DUMMYFUNCTION("""COMPUTED_VALUE"""),100000.0) -> 100000 | E6: =IFERROR(__xludf.DUMMYFUNCTION("""COMPUTED_VALUE"""),10.0) -> 10 | F6: =IFERROR(__xludf.DUMMYFUNCTION("""COMPUTED_VALUE"""),100000.0) -> 100000 | G6: =IFERROR(__xludf.DUMMYFUNCTION("""COMPUTED_VALUE"""),30.0) -> 30 | H6: =IFERROR(__xludf.DUMMYFUNCTION("""COMPUTED_VALUE"""),100.0) -> 100 | I6: =IFERROR(__xludf.DUMMYFUNCTION("""COMPUTED_VALUE"""),70000.0) -> 70000 | J6: =IFERROR(__xludf.DUMMYFUNCTION("""COMPUTED_VALUE"""),100.0) -> 100 | K6: =IFERROR(__xludf.DUMMYFUNCTION("""COMPUTED_VALUE"""),150000.0) -> 150000 | N6: =IFERROR(__xludf.DUMMYFUNCTION("""COMPUTED_VALUE"""),0.0) -> 0 | O6: =IFERROR(__xludf.DUMMYFUNCTION("""COMPUTED_VALUE"""),20.0) -> 20 | P6: =IFERROR(__xludf.DUMMYFUNCTION("""COMPUTED_VALUE"""),70100.0) -> 70100 | Q6: =IFERROR(__xludf.DUMMYFUNCTION("""COMPUTED_VALUE"""),120.0) -> 120 | R6: =IFERROR(__xludf.DUMMYFUNCTION("""COMPUTED_VALUE"""),60000.0) -> 60000 | U6: =IFERROR(__xludf.DUMMYFUNCTION("""COMPUTED_VALUE"""),0.0) -> 0 | X6: =IFERROR(__xludf.DUMMYFUNCTION("""COMPUTED_VALUE"""),0.0) -> 0 | Y6: =IFERROR(__xludf.DUMMYFUNCTION("""COMPUTED_VALUE"""),70000.0) -> 70000 | Z6: =IFERROR(__xludf.DUMMYFUNCTION("""COMPUTED_VALUE"""),5.0) -> 5 | AA6: =IFERROR(__xludf.DUMMYFUNCTION("""COMPUTED_VALUE"""),95000.0) -> 95000 | AB6: =IFERROR(__xludf.DUMMYFUNCTION("""COMPUTED_VALUE"""),100.0) -> 100 | AC6: =IFERROR(__xludf.DUMMYFUNCTION("""COMPUTED_VALUE"""),100.0) -> 100 | AD6: =IFERROR(__xludf.DUMMYFUNCTION("""COMPUTED_VALUE"""),70000.0) -> 70000 | AE6: =IFERROR(__xludf.DUMMYFUNCTION("""COMPUTED_VALUE"""),110.0) -> 110 | AF6: =IFERROR(__xludf.DUMMYFUNCTION("""COMPUTED_VALUE"""),29108.779296875) -> 29108.779 | AI6: =IFERROR(__xludf.DUMMYFUNCTION("""COMPUTED_VALUE"""),0.0) -> 0 | AL6: =IFERROR(__xludf.DUMMYFUNCTION("""COMPUTED_VALUE"""),0.0) -> 0 | AM6: =IFERROR(__xludf.DUMMYFUNCTION("""COMPUTED_VALUE"""),100000.0) -> 100000 | AN6: =IFERROR(__xludf.DUMMYFUNCTION("""COMPUTED_VALUE"""),23.0) -> 23 | AO6: =IFERROR(__xludf.DUMMYFUNCTION("""COMPUTED_VALUE"""),100000.0) -> 100000 | AP6: =IFERROR(__xludf.DUMMYFUNCTION("""COMPUTED_VALUE"""),48.0) -> 48 | AQ6: =IFERROR(__xludf.DUMMYFUNCTION("""COMPUTED_VALUE"""),10.0) -> 10 | AR6: =IFERROR(__xludf.DUMMYFUNCTION("""COMPUTED_VALUE"""),70100.0) -> 70100 | AS6: =IFERROR(__xludf.DUMMYFUNCTION("""COMPUTED_VALUE"""),110.0) -> 110
A7: =IFERROR(__xludf.DUMMYFUNCTION("""COMPUTED_VALUE"""),"ADS") -> ADS | D7: =IFERROR(__xludf.DUMMYFUNCTION("""COMPUTED_VALUE"""),117000.0) -> 117000 | E7: =IFERROR(__xludf.DUMMYFUNCTION("""COMPUTED_VALUE"""),4.0) -> 4 | F7: =IFERROR(__xludf.DUMMYFUNCTION("""COMPUTED_VALUE"""),117000.0) -> 117000 | G7: =IFERROR(__xludf.DUMMYFUNCTION("""COMPUTED_VALUE"""),351.0) -> 351 | H7: =IFERROR(__xludf.DUMMYFUNCTION("""COMPUTED_VALUE"""),10.0) -> 10 | I7: =IFERROR(__xludf.DUMMYFUNCTION("""COMPUTED_VALUE"""),100000.0) -> 100000 | J7: =IFERROR(__xludf.DUMMYFUNCTION("""COMPUTED_VALUE"""),33.0) -> 33 | K7: =IFERROR(__xludf.DUMMYFUNCTION("""COMPUTED_VALUE"""),125000.0) -> 125000 | L7: =IFERROR(__xludf.DUMMYFUNCTION("""COMPUTED_VALUE"""),1.0) -> 1 | M7: =IFERROR(__xludf.DUMMYFUNCTION("""COMPUTED_VALUE"""),120000.0) -> 120000 | N7: =IFERROR(__xludf.DUMMYFUNCTION("""COMPUTED_VALUE"""),95.0) -> 95 | O7: =IFERROR(__xludf.DUMMYFUNCTION("""COMPUTED_VALUE"""),10.0) -> 10 | P7: =IFERROR(__xludf.DUMMYFUNCTION("""COMPUTED_VALUE"""),100000.0) -> 100000 | Q7: =IFERROR(__xludf.DUMMYFUNCTION("""COMPUTED_VALUE"""),20.0) -> 20 | R7: =IFERROR(__xludf.DUMMYFUNCTION("""COMPUTED_VALUE"""),250000.0) -> 250000 | U7: =IFERROR(__xludf.DUMMYFUNCTION("""COMPUTED_VALUE"""),0.0) -> 0 | X7: =IFERROR(__xludf.DUMMYFUNCTION("""COMPUTED_VALUE"""),0.0) -> 0 | Y7: =IFERROR(__xludf.DUMMYFUNCTION("""COMPUTED_VALUE"""),120000.0) -> 120000 | Z7: =IFERROR(__xludf.DUMMYFUNCTION("""COMPUTED_VALUE"""),6.0) -> 6 | AA7: =IFERROR(__xludf.DUMMYFUNCTION("""COMPUTED_VALUE"""),120000.0) -> 120000 | AB7: =IFERROR(__xludf.DUMMYFUNCTION("""COMPUTED_VALUE"""),385.0) -> 385 | AC7: =IFERROR(__xludf.DUMMYFUNCTION("""COMPUTED_VALUE"""),4.0) -> 4 | AD7: =IFERROR(__xludf.DUMMYFUNCTION("""COMPUTED_VALUE"""),114000.0) -> 114000 | AE7: =IFERROR(__xludf.DUMMYFUNCTION("""COMPUTED_VALUE"""),18.0) -> 18 | AF7: =IFERROR(__xludf.DUMMYFUNCTION("""COMPUTED_VALUE"""),55055.921875) -> 55055.922 | AG7: =IFERROR(__xludf.DUMMYFUNCTION("""COMPUTED_VALUE"""),1.0) -> 1 | AH7: =IFERROR(__xludf.DUMMYFUNCTION("""COMPUTED_VALUE"""),128000.0) -> 128000 | AI7: =IFERROR(__xludf.DUMMYFUNCTION("""COMPUTED_VALUE"""),1.0) -> 1 | AL7: =IFERROR(__xludf.DUMMYFUNCTION("""COMPUTED_VALUE"""),0.0) -> 0 | AM7: =IFERROR(__xludf.DUMMYFUNCTION("""COMPUTED_VALUE"""),125000.0) -> 125000 | AN7: =IFERROR(__xludf.DUMMYFUNCTION("""COMPUTED_VALUE"""),91.0) -> 91 | AO7: =IFERROR(__xludf.DUMMYFUNCTION("""COMPUTED_VALUE"""),125000.0) -> 125000 | AP7: =IFERROR(__xludf.DUMMYFUNCTION("""COMPUTED_VALUE"""),256.0) -> 256 | AQ7: =IFERROR(__xludf.DUMMYFUNCTION("""COMPUTED_VALUE"""),10.0) -> 10 | AR7: =IFERROR(__xludf.DUMMYFUNCTION("""COMPUTED_VALUE"""),100000.0) -> 100000 | AS7: =IFERROR(__xludf.DUMMYFUNCTION("""COMPUTED_VALUE"""),27.0) -> 27
A8: =IFERROR(__xludf.DUMMYFUNCTION("""COMPUTED_VALUE"""),"AEF") -> AEF | D8: =IFERROR(__xludf.DUMMYFUNCTION("""COMPUTED_VALUE"""),4800.0) -> 4800 | E8: =IFERROR(__xludf.DUMMYFUNCTION("""COMPUTED_VALUE"""),57.0) -> 57 | F8: =IFERROR(__xludf.DUMMYFUNCTION("""COMPUTED_VALUE"""),5970.0) -> 5970 | G8: =IFERROR(__xludf.DUMMYFUNCTION("""COMPUTED_VALUE"""),1443.0) -> 1443 | H8: =IFERROR(__xludf.DUMMYFUNCTION("""COMPUTED_VALUE"""),146.0) -> 146 | I8: =IFERROR(__xludf.DUMMYFUNCTION("""COMPUTED_VALUE"""),4800.0) -> 4800 | J8: =IFERROR(__xludf.DUMMYFUNCTION("""COMPUTED_VALUE"""),916.0) -> 916 | K8: =IFERROR(__xludf.DUMMYFUNCTION("""COMPUTED_VALUE"""),9500.0) -> 9500 | L8: =IFERROR(__xludf.DUMMYFUNCTION("""COMPUTED_VALUE"""),928.0) -> 928 | M8: =IFERROR(__xludf.DUMMYFUNCTION("""COMPUTED_VALUE"""),9500.0) -> 9500 | N8: =IFERROR(__xludf.DUMMYFUNCTION("""COMPUTED_VALUE"""),1928.0) -> 1928 | O8: =IFERROR(__xludf.DUMMYFUNCTION("""COMPUTED_VALUE"""),491.0) -> 491 | P8: =IFERROR(__xludf.DUMMYFUNCTION("""COMPUTED_VALUE"""),3740.0) -> 3740 | Q8: =IFERROR(__xludf.DUMMYFUNCTION("""COMPUTED_VALUE"""),1338.0) -> 1338 | R8: =IFERROR(__xludf.DUMMYFUNCTION("""COMPUTED_VALUE"""),4000.0) -> 4000 | U8: =IFERROR(__xludf.DUMMYFUNCTION("""COMPUTED_VALUE"""),0.0) -> 0 | X8: =IFERROR(__xludf.DUMMYFUNCTION("""COMPUTED_VALUE"""),0.0) -> 0 | Y8: =IFERROR(__xludf.DUMMYFUNCTION("""COMPUTED_VALUE"""),4230.0) -> 4230 | Z8: =IFERROR(__xludf.DUMMYFUNCTION("""COMPUTED_VALUE"""),7.0) -> 7 | AA8: =IFERROR(__xludf.DUMMYFUNCTION("""COMPUTED_VALUE"""),4990.0) -> 4990 | AB8: =IFERROR(__xludf.DUMMYFUNCTION("""COMPUTED_VALUE"""),3125.0) -> 3125 | AC8: =IFERROR(__xludf.DUMMYFUNCTION("""COMPUTED_VALUE"""),218.0) -> 218 | AD8: =IFERROR(__xludf.DUMMYFUNCTION("""COMPUTED_VALUE"""),4230.0) -> 4230 | AE8: =IFERROR(__xludf.DUMMYFUNCTION("""COMPUTED_VALUE"""),980.0) -> 980 | AF8: =IFERROR(__xludf.DUMMYFUNCTION("""COMPUTED_VALUE"""),4500.0) -> 4500 | AG8: =IFERROR(__xludf.DUMMYFUNCTION("""COMPUTED_VALUE"""),197.0) -> 197 | AH8: =IFERROR(__xludf.DUMMYFUNCTION("""COMPUTED_VALUE"""),4500.0) -> 4500 | AI8: =IFERROR(__xludf.DUMMYFUNCTION("""COMPUTED_VALUE"""),197.0) -> 197 | AL8: =IFERROR(__xludf.DUMMYFUNCTION("""COMPUTED_VALUE"""),0.0) -> 0 | AM8: =IFERROR(__xludf.DUMMYFUNCTION("""COMPUTED_VALUE"""),5793.7099609375) -> 5793.71 | AN8: =IFERROR(__xludf.DUMMYFUNCTION("""COMPUTED_VALUE"""),151.0) -> 151 | AO8: =IFERROR(__xludf.DUMMYFUNCTION("""COMPUTED_VALUE"""),5800.0) -> 5800 | AP8: =IFERROR(__xludf.DUMMYFUNCTION("""COMPUTED_VALUE"""),725.0) -> 725 | AQ8: =IFERROR(__xludf.DUMMYFUNCTION("""COMPUTED_VALUE"""),500.0) -> 500 | AR8: =IFERROR(__xludf.DUMMYFUNCTION("""COMPUTED_VALUE"""),3220.0) -> 3220 | AS8: =IFERROR(__xludf.DUMMYFUNCTION("""COMPUTED_VALUE"""),1560.0) -> 1560
A9: =IFERROR(__xludf.DUMMYFUNCTION("""COMPUTED_VALUE"""),"AEN") -> AEN | D9: =IFERROR(__xludf.DUMMYFUNCTION("""COMPUTED_VALUE"""),2500000.0) -> 2500000 | E9: =IFERROR(__xludf.DUMMYFUNCTION("""COMPUTED_VALUE"""),1.0) -> 1 | F9: =IFERROR(__xludf.DUMMYFUNCTION("""COMPUTED_VALUE"""),2490000.0) -> 2490000 | G9: =IFERROR(__xludf.DUMMYFUNCTION("""COMPUTED_VALUE"""),2.0) -> 2 | J9: =IFERROR(__xludf.DUMMYFUNCTION("""COMPUTED_VALUE"""),0.0) -> 0 | K9: =IFERROR(__xludf.DUMMYFUNCTION("""COMPUTED_VALUE"""),1700000.0) -> 1700000 | L9: =IFERROR(__xludf.DUMMYFUNCTION("""COMPUTED_VALUE"""),1.0) -> 1 | M9: =IFERROR(__xludf.DUMMYFUNCTION("""COMPUTED_VALUE"""),2600000.0) -> 2600000 | N9: =IFERROR(__xludf.DUMMYFUNCTION("""COMPUTED_VALUE"""),1.0) -> 1 | O9: =IFERROR(__xludf.DUMMYFUNCTION("""COMPUTED_VALUE"""),1.0) -> 1 | P9: =IFERROR(__xludf.DUMMYFUNCTION("""COMPUTED_VALUE"""),1000000.0) -> 1000000 | Q9: =IFERROR(__xludf.DUMMYFUNCTION("""COMPUTED_VALUE"""),1.0) -> 1 | R9: =IFERROR(__xludf.DUMMYFUNCTION("""COMPUTED_VALUE"""),974291.3125) -> 974291.31 | U9: =IFERROR(__xludf.DUMMYFUNCTION("""COMPUTED_VALUE"""),0.0) -> 0 | V9: =IFERROR(__xludf.DUMMYFUNCTION("""COMPUTED_VALUE"""),1.0) -> 1 | W9: =IFERROR(__xludf.DUMMYFUNCTION("""COMPUTED_VALUE"""),1000000.0) -> 1000000 | X9: =IFERROR(__xludf.DUMMYFUNCTION("""COMPUTED_VALUE"""),1.0) -> 1 | Y9: =IFERROR(__xludf.DUMMYFUNCTION("""COMPUTED_VALUE"""),2500000.0) -> 2500000 | Z9: =IFERROR(__xludf.DUMMYFUNCTION("""COMPUTED_VALUE"""),1.0) -> 1 | AA9: =IFERROR(__xludf.DUMMYFUNCTION("""COMPUTED_VALUE"""),2600000.0) -> 2600000 | AB9: =IFERROR(__xludf.DUMMYFUNCTION("""COMPUTED_VALUE"""),2.0) -> 2 | AC9: =IFERROR(__xludf.DUMMYFUNCTION("""COMPUTED_VALUE"""),1.0) -> 1 | AD9: =IFERROR(__xludf.DUMMYFUNCTION("""COMPUTED_VALUE"""),2500000.0) -> 2500000 | AE9: =IFERROR(__xludf.DUMMYFUNCTION("""COMPUTED_VALUE"""),6.0) -> 6 | AF9: =IFERROR(__xludf.DUMMYFUNCTION("""COMPUTED_VALUE"""),974291.3125) -> 974291.31 | AI9: =IFERROR(__xludf.DUMMYFUNCTION("""COMPUTED_VALUE"""),0.0) -> 0 | AL9: =IFERROR(__xludf.DUMMYFUNCTION("""COMPUTED_VALUE"""),0.0) -> 0 | AM9: =IFERROR(__xludf.DUMMYFUNCTION("""COMPUTED_VALUE"""),974291.3125) -> 974291.31 | AN9: =IFERROR(__xludf.DUMMYFUNCTION("""COMPUTED_VALUE"""),1.0) -> 1 | AO9: =IFERROR(__xludf.DUMMYFUNCTION("""COMPUTED_VALUE"""),2600000.0) -> 2600000 | AP9: =IFERROR(__xludf.DUMMYFUNCTION("""COMPUTED_VALUE"""),1.0) -> 1 | AS9: =IFERROR(__xludf.DUMMYFUNCTION("""COMPUTED_VALUE"""),0.0) -> 0
A10: =IFERROR(__xludf.DUMMYFUNCTION("""COMPUTED_VALUE"""),"AFP") -> AFP | D10: =IFERROR(__xludf.DUMMYFUNCTION("""COMPUTED_VALUE"""),134241.84375) -> 134241.84 | G10: =IFERROR(__xludf.DUMMYFUNCTION("""COMPUTED_VALUE"""),0.0) -> 0 | J10: =IFERROR(__xludf.DUMMYFUNCTION("""COMPUTED_VALUE"""),0.0) -> 0 | K10: =IFERROR(__xludf.DUMMYFUNCTION("""COMPUTED_VALUE"""),134241.84375) -> 134241.84 | N10: =IFERROR(__xludf.DUMMYFUNCTION("""COMPUTED_VALUE"""),0.0) -> 0 | O10: =IFERROR(__xludf.DUMMYFUNCTION("""COMPUTED_VALUE"""),4.0) -> 4 | P10: =IFERROR(__xludf.DUMMYFUNCTION("""COMPUTED_VALUE"""),195000.0) -> 195000 | Q10: =IFERROR(__xludf.DUMMYFUNCTION("""COMPUTED_VALUE"""),4.0) -> 4 | R10: =IFERROR(__xludf.DUMMYFUNCTION("""COMPUTED_VALUE"""),134241.84375) -> 134241.84 | U10: =IFERROR(__xludf.DUMMYFUNCTION("""COMPUTED_VALUE"""),0.0) -> 0 | X10: =IFERROR(__xludf.DUMMYFUNCTION("""COMPUTED_VALUE"""),0.0) -> 0 | Y10: =IFERROR(__xludf.DUMMYFUNCTION("""COMPUTED_VALUE"""),30000.0) -> 30000 | AB10: =IFERROR(__xludf.DUMMYFUNCTION("""COMPUTED_VALUE"""),0.0) -> 0 | AE10: =IFERROR(__xludf.DUMMYFUNCTION("""COMPUTED_VALUE"""),0.0) -> 0 | AF10: =IFERROR(__xludf.DUMMYFUNCTION("""COMPUTED_VALUE"""),134241.84375) -> 134241.84 | AI10: =IFERROR(__xludf.DUMMYFUNCTION("""COMPUTED_VALUE"""),0.0) -> 0 | AL10: =IFERROR(__xludf.DUMMYFUNCTION("""COMPUTED_VALUE"""),0.0) -> 0 | AM10: =IFERROR(__xludf.DUMMYFUNCTION("""COMPUTED_VALUE"""),134241.84375) -> 134241.84 | AP10: =IFERROR(__xludf.DUMMYFUNCTION("""COMPUTED_VALUE"""),0.0) -> 0 | AS10: =IFERROR(__xludf.DUMMYFUNCTION("""COMPUTED_VALUE"""),0.0) -> 0
A11: =IFERROR(__xludf.DUMMYFUNCTION("""COMPUTED_VALUE"""),"AFR") -> AFR | D11: =IFERROR(__xludf.DUMMYFUNCTION("""COMPUTED_VALUE"""),17000.0) -> 17000 | E11: =IFERROR(__xludf.DUMMYFUNCTION("""COMPUTED_VALUE"""),10.0) -> 10 | F11: =IFERROR(__xludf.DUMMYFUNCTION("""COMPUTED_VALUE"""),23500.0) -> 23500 | G11: =IFERROR(__xludf.DUMMYFUNCTION("""COMPUTED_VALUE"""),129.0) -> 129 | H11: =IFERROR(__xludf.DUMMYFUNCTION("""COMPUTED_VALUE"""),36.0) -> 36 | I11: =IFERROR(__xludf.DUMMYFUNCTION("""COMPUTED_VALUE"""),17000.0) -> 17000 | J11: =IFERROR(__xludf.DUMMYFUNCTION("""COMPUTED_VALUE"""),45.0) -> 45 | K11: =IFERROR(__xludf.DUMMYFUNCTION("""COMPUTED_VALUE"""),20000.0) -> 20000 | N11: =IFERROR(__xludf.DUMMYFUNCTION("""COMPUTED_VALUE"""),0.0) -> 0 | O11: =IFERROR(__xludf.DUMMYFUNCTION("""COMPUTED_VALUE"""),18.0) -> 18 | P11: =IFERROR(__xludf.DUMMYFUNCTION("""COMPUTED_VALUE"""),20000.0) -> 20000 | Q11: =IFERROR(__xludf.DUMMYFUNCTION("""COMPUTED_VALUE"""),38.0) -> 38 | R11: =IFERROR(__xludf.DUMMYFUNCTION("""COMPUTED_VALUE"""),7797.1201171875) -> 7797.1201 | U11: =IFERROR(__xludf.DUMMYFUNCTION("""COMPUTED_VALUE"""),0.0) -> 0 | X11: =IFERROR(__xludf.DUMMYFUNCTION("""COMPUTED_VALUE"""),0.0) -> 0 | Y11: =IFERROR(__xludf.DUMMYFUNCTION("""COMPUTED_VALUE"""),18000.0) -> 18000 | Z11: =IFERROR(__xludf.DUMMYFUNCTION("""COMPUTED_VALUE"""),73.0) -> 73 | AA11: =IFERROR(__xludf.DUMMYFUNCTION("""COMPUTED_VALUE"""),18000.0) -> 18000 | AB11: =IFERROR(__xludf.DUMMYFUNCTION("""COMPUTED_VALUE"""),73.0) -> 73 | AE11: =IFERROR(__xludf.DUMMYFUNCTION("""COMPUTED_VALUE"""),0.0) -> 0 | AF11: =IFERROR(__xludf.DUMMYFUNCTION("""COMPUTED_VALUE"""),7797.1201171875) -> 7797.1201 | AI11: =IFERROR(__xludf.DUMMYFUNCTION("""COMPUTED_VALUE"""),0.0) -> 0 | AL11: =IFERROR(__xludf.DUMMYFUNCTION("""COMPUTED_VALUE"""),0.0) -> 0 | AM11: =IFERROR(__xludf.DUMMYFUNCTION("""COMPUTED_VALUE"""),20000.0) -> 20000 | AN11: =IFERROR(__xludf.DUMMYFUNCTION("""COMPUTED_VALUE"""),20.0) -> 20 | AO11: =IFERROR(__xludf.DUMMYFUNCTION("""COMPUTED_VALUE"""),24000.0) -> 24000 | AP11: =IFERROR(__xludf.DUMMYFUNCTION("""COMPUTED_VALUE"""),20.0) -> 20 | AS11: =IFERROR(__xludf.DUMMYFUNCTION("""COMPUTED_VALUE"""),0.0) -> 0
A12: =IFERROR(__xludf.DUMMYFUNCTION("""COMPUTED_VALUE"""),"AGS") -> AGS | D12: =IFERROR(__xludf.DUMMYFUNCTION("""COMPUTED_VALUE"""),250000.0) -> 250000 | E12: =IFERROR(__xludf.DUMMYFUNCTION("""COMPUTED_VALUE"""),1.0) -> 1 | F12: =IFERROR(__xludf.DUMMYFUNCTION("""COMPUTED_VALUE"""),489000.0) -> 489000 | G12: =IFERROR(__xludf.DUMMYFUNCTION("""COMPUTED_VALUE"""),7.0) -> 7 | J12: =IFERROR(__xludf.DUMMYFUNCTION("""COMPUTED_VALUE"""),0.0) -> 0 | K12: =IFERROR(__xludf.DUMMYFUNCTION("""COMPUTED_VALUE"""),598000.0) -> 598000 | L12: =IFERROR(__xludf.DUMMYFUNCTION("""COMPUTED_VALUE"""),1.0) -> 1 | M12: =IFERROR(__xludf.DUMMYFUNCTION("""COMPUTED_VALUE"""),598000.0) -> 598000 | N12: =IFERROR(__xludf.DUMMYFUNCTION("""COMPUTED_VALUE"""),2.0) -> 2 | O12: =IFERROR(__xludf.DUMMYFUNCTION("""COMPUTED_VALUE"""),1.0) -> 1 | P12: =IFERROR(__xludf.DUMMYFUNCTION("""COMPUTED_VALUE"""),399000.0) -> 399000 | Q12: =IFERROR(__xludf.DUMMYFUNCTION("""COMPUTED_VALUE"""),1.0) -> 1 | R12: =IFERROR(__xludf.DUMMYFUNCTION("""COMPUTED_VALUE"""),500000.0) -> 500000 | U12: =IFERROR(__xludf.DUMMYFUNCTION("""COMPUTED_VALUE"""),0.0) -> 0 | X12: =IFERROR(__xludf.DUMMYFUNCTION("""COMPUTED_VALUE"""),0.0) -> 0 | Y12: =IFERROR(__xludf.DUMMYFUNCTION("""COMPUTED_VALUE"""),599000.0) -> 599000 | Z12: =IFERROR(__xludf.DUMMYFUNCTION("""COMPUTED_VALUE"""),1.0) -> 1 | AA12: =IFERROR(__xludf.DUMMYFUNCTION("""COMPUTED_VALUE"""),598000.0) -> 598000 | AB12: =IFERROR(__xludf.DUMMYFUNCTION("""COMPUTED_VALUE"""),9.0) -> 9 | AC12: =IFERROR(__xludf.DUMMYFUNCTION("""COMPUTED_VALUE"""),1.0) -> 1 | AD12: =IFERROR(__xludf.DUMMYFUNCTION("""COMPUTED_VALUE"""),500000.0) -> 500000 | AE12: =IFERROR(__xludf.DUMMYFUNCTION("""COMPUTED_VALUE"""),1.0) -> 1 | AF12: =IFERROR(__xludf.DUMMYFUNCTION("""COMPUTED_VALUE"""),219398.5) -> 219398.5 | AI12: =IFERROR(__xludf.DUMMYFUNCTION("""COMPUTED_VALUE"""),0.0) -> 0 | AL12: =IFERROR(__xludf.DUMMYFUNCTION("""COMPUTED_VALUE"""),0.0) -> 0 | AM12: =IFERROR(__xludf.DUMMYFUNCTION("""COMPUTED_VALUE"""),798000.0) -> 798000 | AN12: =IFERROR(__xludf.DUMMYFUNCTION("""COMPUTED_VALUE"""),1.0) -> 1 | AO12: =IFERROR(__xludf.DUMMYFUNCTION("""COMPUTED_VALUE"""),798000.0) -> 798000 | AP12: =IFERROR(__xludf.DUMMYFUNCTION("""COMPUTED_VALUE"""),3.0) -> 3 | AS12: =IFERROR(__xludf.DUMMYFUNCTION("""COMPUTED_VALUE"""),0.0) -> 0
A13: =IFERROR(__xludf.DUMMYFUNCTION("""COMPUTED_VALUE"""),"AHP") -> AHP | D13: =IFERROR(__xludf.DUMMYFUNCTION("""COMPUTED_VALUE"""),11278.8701171875) -> 11278.87 | E13: =IFERROR(__xludf.DUMMYFUNCTION("""COMPUTED_VALUE"""),565.0) -> 565 | F13: =IFERROR(__xludf.DUMMYFUNCTION("""COMPUTED_VALUE"""),12000.0) -> 12000 | G13: =IFERROR(__xludf.DUMMYFUNCTION("""COMPUTED_VALUE"""),1653.0) -> 1653 | H13: =IFERROR(__xludf.DUMMYFUNCTION("""COMPUTED_VALUE"""),50.0) -> 50 | I13: =IFERROR(__xludf.DUMMYFUNCTION("""COMPUTED_VALUE"""),8670.0) -> 8670 | J13: =IFERROR(__xludf.DUMMYFUNCTION("""COMPUTED_VALUE"""),52.0) -> 52 | K13: =IFERROR(__xludf.DUMMYFUNCTION("""COMPUTED_VALUE"""),13000.0) -> 13000 | L13: =IFERROR(__xludf.DUMMYFUNCTION("""COMPUTED_VALUE"""),362.0) -> 362 | M13: =IFERROR(__xludf.DUMMYFUNCTION("""COMPUTED_VALUE"""),13000.0) -> 13000 | N13: =IFERROR(__xludf.DUMMYFUNCTION("""COMPUTED_VALUE"""),362.0) -> 362 | Q13: =IFERROR(__xludf.DUMMYFUNCTION("""COMPUTED_VALUE"""),0.0) -> 0 | R13: =IFERROR(__xludf.DUMMYFUNCTION("""COMPUTED_VALUE"""),5547.2099609375) -> 5547.21 | U13: =IFERROR(__xludf.DUMMYFUNCTION("""COMPUTED_VALUE"""),0.0) -> 0 | X13: =IFERROR(__xludf.DUMMYFUNCTION("""COMPUTED_VALUE"""),0.0) -> 0 | Y13: =IFERROR(__xludf.DUMMYFUNCTION("""COMPUTED_VALUE"""),9500.0) -> 9500 | Z13: =IFERROR(__xludf.DUMMYFUNCTION("""COMPUTED_VALUE"""),400.0) -> 400 | AA13: =IFERROR(__xludf.DUMMYFUNCTION("""COMPUTED_VALUE"""),13000.0) -> 13000 | AB13: =IFERROR(__xludf.DUMMYFUNCTION("""COMPUTED_VALUE"""),1972.0) -> 1972 | AC13: =IFERROR(__xludf.DUMMYFUNCTION("""COMPUTED_VALUE"""),99.0) -> 99 | AD13: =IFERROR(__xludf.DUMMYFUNCTION("""COMPUTED_VALUE"""),9500.0) -> 9500 | AE13: =IFERROR(__xludf.DUMMYFUNCTION("""COMPUTED_VALUE"""),245.0) -> 245 | AF13: =IFERROR(__xludf.DUMMYFUNCTION("""COMPUTED_VALUE"""),5547.2099609375) -> 5547.21 | AI13: =IFERROR(__xludf.DUMMYFUNCTION("""COMPUTED_VALUE"""),0.0) -> 0 | AL13: =IFERROR(__xludf.DUMMYFUNCTION("""COMPUTED_VALUE"""),0.0) -> 0 | AM13: =IFERROR(__xludf.DUMMYFUNCTION("""COMPUTED_VALUE"""),12000.0) -> 12000 | AN13: =IFERROR(__xludf.DUMMYFUNCTION("""COMPUTED_VALUE"""),124.0) -> 124 | AO13: =IFERROR(__xludf.DUMMYFUNCTION("""COMPUTED_VALUE"""),12000.0) -> 12000 | AP13: =IFERROR(__xludf.DUMMYFUNCTION("""COMPUTED_VALUE"""),361.0) -> 361 | AS13: =IFERROR(__xludf.DUMMYFUNCTION("""COMPUTED_VALUE"""),0.0) -> 0
